Workbook

Sheet Resumo Farm Anual
C2: Coin Mediana | D2: Farm Total KK | E2: Farm Mediana | F2: Eficiência | G2: Média Rotação | H2: Média Hunt | I2: Média Drop | J2: Status | K2: % meta | L2: Dias Jogados | M2: Folgas Realizadas
B3: Janeiro | C3: =Janeiro!$M$8 -> 40575.5 | D3: =Janeiro!$M$10 -> 214209070 | E3: =Janeiro!$M$9 -> 8763490.5 | F3: =IFERROR(D3/L3, 0) -> 8925377.9 | G3: =IFERROR(AVERAGE(Janeiro!$D$7:$D$37), ) -> 5542493.8 | H3: =IFERROR(AVERAGE(Janeiro!$E$7:$E$37), 0) -> 2778717.5 | I3: =IFERROR(AVERAGE(Janeiro!$F$7:$F$37), 0) -> 604166.67 | J3: =if(Janeiro!$R$13 = "🔵 Concluído","Ok", "No") -> Ok | K3: =IFERROR(D3/Janeiro!$M$11, 0) -> 1.0558542 | L3: =Janeiro!$R$9 -> 24 | M3: =Janeiro!$R$11 -> 7
B4: Fevereiro | C4: =Fevereiro!$M$8 -> 39997 | D4: =Fevereiro!$M$10 -> 216933187 | E4: =Fevereiro!$M$9 -> 7936121 | F4: =IFERROR(D4/L4, 0) -> 7747613.8 | G4: =IFERROR(AVERAGE(Fevereiro!$D$7:$D$37), 0) -> 4879658 | H4: =IFERROR(AVERAGE(Fevereiro!$E$7:$E$37), 0) -> 2589241 | I4: =IFERROR(AVERAGE(Fevereiro!$F$7:$F$37), 0) -> 289037.59 | J4: =if(Fevereiro!$R$13 = "🔵 Concluído","Ok", "No") -> Ok | K4: =IFERROR(D4/Fevereiro!$M$11, 0) -> 1.0847473 | L4: =Fevereiro!$R$9 -> 28 | M4: =Fevereiro!$R$11 -> 0
B5: Março | C5: ='Março'!$M$8 -> 38498 | D5: ='Março'!$M$10 -> 208999761 | E5: ='Março'!$M$9 -> 7255621 | F5: =IFERROR(D5/L5, 0) -> 6741927.8 | G5: =IFERROR(AVERAGE('Março'!$D$7:$D$37), 0) -> 3988847 | H5: =IFERROR(AVERAGE('Março'!$E$7:$E$37), 0) -> 2675594.9 | I5: =IFERROR(AVERAGE('Março'!$F$7:$F$37), 0) -> 77485.871 | J5: =if('Março'!$R$13 = "🔵 Concluído","Ok", "No") -> Ok | K5: =IFERROR(D5/'Março'!$M$11, 0) -> 1.0857694 | L5: ='Março'!$R$9 -> 31 | M5: ='Março'!$R$11 -> 0
B6: Abril | C6: =Abril!$M$8 -> 38396 | D6: =Abril!$M$10 -> 0 | E6: =Abril!$M$9 | F6: =IFERROR(D6/L6, 0) -> 0 | G6: =IFERROR(AVERAGE(Abril!$D$7:$D$37), 0) -> 0 | H6: =IFERROR(AVERAGE(Abril!$E$7:$E$37), 0) -> 0 | I6: =IFERROR(AVERAGE(Abril!$F$7:$F$37), 0) -> 0 | J6: =if(Abril!$R$13 = "🔵 Concluído","Ok", "No") -> No | K6: =IFERROR(D6/Abril!$M$11, 0) -> 0 | L6: =Abril!$R$9 -> 0 | M6: =Abril!$R$11 -> 1
B7: Maio | C7: =Maio!$M$8 | D7: =Maio!$M$10 -> 0 | E7: =Maio!$M$9 | F7: =IFERROR(D7/L7, 0) -> 0 | G7: =IFERROR(AVERAGE(Maio!$D$7:$D$37), 0) -> 0 | H7: =IFERROR(AVERAGE(Maio!$E$7:$E$37), 0) -> 0 | I7: =IFERROR(AVERAGE(Maio!$F$7:$F$37), 0) -> 0 | J7: =if(Maio!$R$13 = "🔵 Concluído","Ok", "No") -> Ok | K7: =IFERROR(D7/Maio!$M$11, 0) -> 0 | L7: =Maio!$R$9 -> 0 | M7: =Maio!$R$11 -> 0
B8: Junho | C8: =Junho!$M$8 | D8: =Junho!$M$10 -> 0 | E8: =Junho!$M$9 | F8: =IFERROR(D8/L8, 0) -> 0 | G8: =IFERROR(AVERAGE(Junho!$D$7:$D$37), 0) -> 0 | H8: =IFERROR(AVERAGE(Junho!$E$7:$E$37), 0) -> 0 | I8: =IFERROR(AVERAGE(Junho!$F$7:$F$37), 0) -> 0 | J8: =if(Junho!$R$13 = "🔵 Concluído","Ok", "No") -> Ok | K8: =IFERROR(D8/Junho!$M$11, 0) -> 0 | L8: =Junho!$R$9 -> 0 | M8: =Junho!$R$11 -> 0
B9: Julho | C9: =Julho!$M$8 | D9: =Julho!$M$10 -> 0 | E9: =Julho!$M$9 | F9: =IFERROR(D9/L9, 0) -> 0 | G9: =IFERROR(AVERAGE(Julho!$D$7:$D$37), 0) -> 0 | H9: =IFERROR(AVERAGE(Julho!$E$7:$E$37), 0) -> 0 | I9: =IFERROR(AVERAGE(Julho!$F$7:$F$37), 0) -> 0 | J9: =if(Julho!$R$13 = "🔵 Concluído","Ok", "No") -> Ok | K9: =IFERROR(D9/Julho!$M$11, 0) -> 0 | L9: =Julho!$R$9 -> 0 | M9: =Julho!$R$11 -> 0
B10: Agosto | C10: =Agosto!$M$8 | D10: =Agosto!$M$10 -> 0 | E10: =Agosto!$M$9 | F10: =IFERROR(D10/L10, 0) -> 0 | G10: =IFERROR(AVERAGE(Agosto!$D$7:$D$37), 0) -> 0 | H10: =IFERROR(AVERAGE(Agosto!$E$7:$E$37), 0) -> 0 | I10: =IFERROR(AVERAGE(Agosto!$F$7:$F$37), 0) -> 0 | J10: =if(Agosto!$R$13 = "🔵 Concluído","Ok", "No") -> Ok | K10: =IFERROR(D10/Agosto!$M$11, 0) -> 0 | L10: =Agosto!$R$9 -> 0 | M10: =Agosto!$R$11 -> 0
B11: Setembro | C11: =Setembro!$M$8 | D11: =Setembro!$M$10 -> 0 | E11: =Setembro!$M$9 | F11: =IFERROR(D11/L11, 0) -> 0 | G11: =IFERROR(AVERAGE(Setembro!$D$7:$D$37), 0) -> 0 | H11: =IFERROR(AVERAGE(Setembro!$E$7:$E$37), 0) -> 0 | I11: =IFERROR(AVERAGE(Setembro!$F$7:$F$37), 0) -> 0 | J11: =if(Setembro!$R$13 = "🔵 Concluído","Ok", "No") -> Ok | K11: =IFERROR(D11/Setembro!$M$11, 0) -> 0 | L11: =Setembro!$R$9 -> 0 | M11: =Setembro!$R$11 -> 0
B12: Outubro | C12: =Outubro!$M$8 | D12: =Outubro!$M$10 -> 0 | E12: =Outubro!$M$9 | F12: =IFERROR(D12/L12, 0) -> 0 | G12: =IFERROR(AVERAGE(Outubro!$D$7:$D$37), 0) -> 0 | H12: =IFERROR(AVERAGE(Outubro!$E$7:$E$37), 0) -> 0 | I12: =IFERROR(AVERAGE(Outubro!$F$7:$F$37), 0) -> 0 | J12: =if(Outubro!$R$13 = "🔵 Concluído","Ok", "No") -> Ok | K12: =IFERROR(D12/Outubro!$M$11, 0) -> 0 | L12: =Outubro!$R$9 -> 0 | M12: =Outubro!$R$11 -> 0
B13: Novembro | C13: =Novembro!$M$8 | D13: =Novembro!$M$10 -> 0 | E13: =Novembro!$M$9 | F13: =IFERROR(D13/L13, 0) -> 0 | G13: =IFERROR(AVERAGE(Novembro!$D$7:$D$37), 0) -> 0 | H13: =IFERROR(AVERAGE(Novembro!$E$7:$E$37), 0) -> 0 | I13: =IFERROR(AVERAGE(Novembro!$F$7:$F$37), 0) -> 0 | J13: =if(Novembro!$R$13 = "🔵 Concluído","Ok", "No") -> Ok | K13: =IFERROR(D13/Novembro!$M$11, 0) -> 0 | L13: =Novembro!$R$9 -> 0 | M13: =Novembro!$R$11 -> 0
B14: Dezembro | C14: =Dezembro!$M$8 | D14: =Dezembro!$M$10 -> 0 | E14: =Dezembro!$M$9 | F14: =IFERROR(D14/L14, 0) -> 0 | G14: =IFERROR(AVERAGE(Dezembro!$D$7:$D$37), 0) -> 0 | H14: =IFERROR(AVERAGE(Dezembro!$E$7:$E$37), 0) -> 0 | I14: =IFERROR(AVERAGE(Dezembro!$F$7:$F$37), 0) -> 0 | J14: =if(Dezembro!$R$13 = "🔵 Concluído","Ok", "No") -> Ok | K14: =IFERROR(D14/Dezembro!$M$11, 0) -> 0 | L14: =Dezembro!$R$9 -> 0 | M14: =Dezembro!$R$11 -> 0

Sheet Extrato R$
B2: Controle de Movimentação de TC | J2: Extrato Mensal
B3: Data | C3: Mês/Ano | D3: Tipo | E3: Qntd TC | F3: Preço (R$/250 TC) | G3: Valor em R$ | J3: TC Comprados | K3: TC Gastos | L3: TC Vendidos | M3: Saldo TC | N3: Preço mediano (R$/250 TC) | O3: R$ Vendidos
B4: 46024 | C4: =(TEXT(B4,"mm/yyyy")) -> 01/2026 | D4: Compra | E4: 100 | F4: 53.5 | G4: =E4/250 * F4 -> 21.4 | I4: Janeiro | J4: =SUMIFS($E$4:$E1003,$C$4:$C1003,"2026-01",$D$4:$D1003,"Compra") -> 4500 | K4: =SUMIFS($E$4:$E1003,$C$4:$C1003,"2026-01",$D$4:$D1003,"Uso") -> 250 | L4: =SUMIFS($E$4:$E1003,$C$4:$C1003,"2026-01",$D$4:$D1003,"Venda") -> 0 | M4: =J4 - K4 - L4 -> 4250 | N4: =IFERROR(__xludf.DUMMYFUNCTION("IFERROR(MEDIAN(FILTER($F$4:$F1003,$C$4:$C1003=""01/2026"",$D$4:$D1003=""Compra""), ), 0 )"),53.5) -> 53.5 | O4: =L4/250 * N4 -> 0
B5: 46025 | C5: =(TEXT(B5,"mm/yyyy")) -> 01/2026 | D5: Compra | E5: 250 | F5: 53.5 | G5: =E5/250 * F5 -> 53.5 | I5: Fevereiro | J5: =SUMIFS($E$4:$E1003,$C$4:$C1003,"2026-02",$D$4:$D1003,"Compra") -> 4525 | K5: =SUMIFS($E$4:$E1003,$C$4:$C1003,"2026-02",$D$4:$D1003,"Uso") -> 400 | L5: =SUMIFS($E$4:$E1003,$C$4:$C1003,"2026-02",$D$4:$D1003,"Venda") -> 7000 | M5: =M4 + J5 - K5 - L5 -> 1375 | N5: =IFERROR(__xludf.DUMMYFUNCTION("IFERROR(MEDIAN(FILTER($F$4:$F1003,$C$4:$C1003=""02/2026"",$D$4:$D1003=""Compra""), ), 0 )"),52.0) -> 52 | O5: =L5/250 * N5 -> 1456
B6: 46025 | C6: =(TEXT(B6,"mm/yyyy")) -> 01/2026 | D6: Compra | E6: 250 | F6: 53.5 | G6: =E6/250 * F6 -> 53.5 | I6: Março | J6: =SUMIFS($E$4:$E1003,$C$4:$C1003,"2026-03",$D$4:$D1003,"Compra") -> 4850 | K6: =SUMIFS($E$4:$E1003,$C$4:$C1003,"2026-03",$D$4:$D1003,"Uso") -> 2725 | L6: =SUMIFS($E$4:$E1003,$C$4:$C1003,"2026-03",$D$4:$D1003,"Venda") -> 3000 | M6: =M5 + J6 - K6 - L6 -> 500 | N6: =IFERROR(__xludf.DUMMYFUNCTION("IFERROR(MEDIAN(FILTER($F$4:$F1003,$C$4:$C1003=""03/2026"",$D$4:$D1003=""Compra""), ), 0 )"),51.0) -> 51 | O6: =L6/250 * N6 -> 612
B7: 46027 | C7: =(TEXT(B7,"mm/yyyy")) -> 01/2026 | D7: Compra | E7: 150 | F7: 53.5 | G7: =E7/250 * F7 -> 32.1 | I7: Abril | J7: =SUMIFS($E$4:$E1003,$C$4:$C1003,"2026-04",$D$4:$D1003,"Compra") -> 0 | K7: =SUMIFS($E$4:$E1003,$C$4:$C1003,"2026-04",$D$4:$D1003,"Uso") -> 0 | L7: =SUMIFS($E$4:$E1003,$C$4:$C1003,"2026-04",$D$4:$D1003,"Venda") -> 0 | M7: =J7 - K7 - L7 -> 0 | N7: =IFERROR(__xludf.DUMMYFUNCTION("IFERROR(MEDIAN(FILTER($F$4:$F1003,$C$4:$C1003=""04/2026"",$D$4:$D1003=""Compra""), ), 0 )"),0.0) -> 0 | O7: =L7/250 * N7 -> 0
B8: 46028 | C8: =(TEXT(B8,"mm/yyyy")) -> 01/2026 | D8: Compra | E8: 100 | F8: 53.5 | G8: =E8/250 * F8 -> 21.4 | I8: Maio | J8: =SUMIFS($E$4:$E1003,$C$4:$C1003,"2026-05",$D$4:$D1003,"Compra") -> 0 | K8: =SUMIFS($E$4:$E1003,$C$4:$C1003,"2026-05",$D$4:$D1003,"Uso") -> 0 | L8: =SUMIFS($E$4:$E1003,$C$4:$C1003,"2026-05",$D$4:$D1003,"Venda") -> 0 | M8: =J8 - K8 - L8 -> 0 | N8: =IFERROR(__xludf.DUMMYFUNCTION("IFERROR(MEDIAN(FILTER($F$4:$F1003,$C$4:$C1003=""05/2026"",$D$4:$D1003=""Compra""), ), 0 )"),0.0) -> 0 | O8: =L8/250 * N8 -> 0
B9: 46029 | C9: =(TEXT(B9,"mm/yyyy")) -> 01/2026 | D9: Compra | E9: 250 | F9: 53.5 | G9: =E9/250 * F9 -> 53.5 | I9: Junho | J9: =SUMIFS($E$4:$E1003,$C$4:$C1003,"2026-06",$D$4:$D1003,"Compra") -> 0 | K9: =SUMIFS($E$4:$E1003,$C$4:$C1003,"2026-06",$D$4:$D1003,"Uso") -> 0 | L9: =SUMIFS($E$4:$E1003,$C$4:$C1003,"2026-06",$D$4:$D1003,"Venda") -> 0 | M9: =J9 - K9 - L9 -> 0 | N9: =IFERROR(__xludf.DUMMYFUNCTION("IFERROR(MEDIAN(FILTER($F$4:$F1003,$C$4:$C1003=""06/2026"",$D$4:$D1003=""Compra""), ), 0 )"),0.0) -> 0 | O9: =L9/250 * N9 -> 0
B10: 46024 | C10: =(TEXT(B10,"mm/yyyy")) -> 01/2026 | D10: Compra | E10: 150 | F10: 53.5 | G10: =E10/250 * F10 -> 32.1 | I10: Julho | J10: =SUMIFS($E$4:$E1003,$C$4:$C1003,"2026-07",$D$4:$D1003,"Compra") -> 0 | K10: =SUMIFS($E$4:$E1003,$C$4:$C1003,"2026-07",$D$4:$D1003,"Uso") -> 0 | L10: =SUMIFS($E$4:$E1003,$C$4:$C1003,"2026-07",$D$4:$D1003,"Venda") -> 0 | M10: =J10 - K10 - L10 -> 0 | N10: =IFERROR(__xludf.DUMMYFUNCTION("IFERROR(MEDIAN(FILTER($F$4:$F1003,$C$4:$C1003=""07/2026"",$D$4:$D1003=""Compra""), ), 0 )"),0.0) -> 0 | O10: =L10/250 * N10 -> 0
B11: 46029 | C11: =(TEXT(B11,"mm/yyyy")) -> 01/2026 | D11: Uso | E11: 250 | F11: 53.5 | G11: =E11/250 * F11 -> 53.5 | I11: Agosto | J11: =SUMIFS($E$4:$E1003,$C$4:$C1003,"2026-08",$D$4:$D1003,"Compra") -> 0 | K11: =SUMIFS($E$4:$E1003,$C$4:$C1003,"2026-08",$D$4:$D1003,"Uso") -> 0 | L11: =SUMIFS($E$4:$E1003,$C$4:$C1003,"2026-08",$D$4:$D1003,"Venda") -> 0 | M11: =J11 - K11 - L11 -> 0 | N11: =IFERROR(__xludf.DUMMYFUNCTION("IFERROR(MEDIAN(FILTER($F$4:$F1003,$C$4:$C1003=""08/2026"",$D$4:$D1003=""Compra""), ), 0 )"),0.0) -> 0 | O11: =L11/250 * N11 -> 0
B12: 46036 | C12: =(TEXT(B12,"mm/yyyy")) -> 01/2026 | D12: Compra | E12: 750 | F12: 53.5 | G12: =E12/250 * F12 -> 160.5 | I12: Setembro | J12: =SUMIFS($E$4:$E1003,$C$4:$C1003,"2026-09",$D$4:$D1003,"Compra") -> 0 | K12: =SUMIFS($E$4:$E1003,$C$4:$C1003,"2026-09",$D$4:$D1003,"Uso") -> 0 | L12: =SUMIFS($E$4:$E1003,$C$4:$C1003,"2026-09",$D$4:$D1003,"Venda") -> 0 | M12: =J12 - K12 - L12 -> 0 | N12: =IFERROR(__xludf.DUMMYFUNCTION("IFERROR(MEDIAN(FILTER($F$4:$F1003,$C$4:$C1003=""09/2026"",$D$4:$D1003=""Compra""), ), 0 )"),0.0) -> 0 | O12: =L12/250 * N12 -> 0
B13: 46041 | C13: =(TEXT(B13,"mm/yyyy")) -> 01/2026 | D13: Compra | E13: 250 | F13: 53.5 | G13: =E13/250 * F13 -> 53.5 | I13: Outubro | J13: =SUMIFS($E$4:$E1003,$C$4:$C1003,"2026-10",$D$4:$D1003,"Compra") -> 0 | K13: =SUMIFS($E$4:$E1003,$C$4:$C1003,"2026-10",$D$4:$D1003,"Uso") -> 0 | L13: =SUMIFS($E$4:$E1003,$C$4:$C1003,"2026-10",$D$4:$D1003,"Venda") -> 0 | M13: =J13 - K13 - L13 -> 0 | N13: =IFERROR(__xludf.DUMMYFUNCTION("IFERROR(MEDIAN(FILTER($F$4:$F1003,$C$4:$C1003=""10/2026"",$D$4:$D1003=""Compra""), ), 0 )"),0.0) -> 0 | O13: =L13/250 * N13 -> 0
B14: 46044 | C14: =(TEXT(B14,"mm/yyyy")) -> 01/2026 | D14: Compra | E14: 500 | F14: 53.5 | G14: =E14/250 * F14 -> 107 | I14: Novembro | J14: =SUMIFS($E$4:$E1003,$C$4:$C1003,"2026-11",$D$4:$D1003,"Compra") -> 0 | K14: =SUMIFS($E$4:$E1003,$C$4:$C1003,"2026-11",$D$4:$D1003,"Uso") -> 0 | L14: =SUMIFS($E$4:$E1003,$C$4:$C1003,"2026-11",$D$4:$D1003,"Venda") -> 0 | M14: =J14 - K14 - L14 -> 0 | N14: =IFERROR(__xludf.DUMMYFUNCTION("IFERROR(MEDIAN(FILTER($F$4:$F1003,$C$4:$C1003=""11/2026"",$D$4:$D1003=""Compra""), ), 0 )"),0.0) -> 0 | O14: =L14/250 * N14 -> 0
B15: 46045 | C15: =(TEXT(B15,"mm/yyyy")) -> 01/2026 | D15: Compra | E15: 250 | F15: 53.5 | G15: =E15/250 * F15 -> 53.5 | I15: Dezembro | J15: =SUMIFS($E$4:$E1003,$C$4:$C1003,"2026-12",$D$4:$D1003,"Compra") -> 0 | K15: =SUMIFS($E$4:$E1003,$C$4:$C1003,"2026-12",$D$4:$D1003,"Uso") -> 0 | L15: =SUMIFS($E$4:$E1003,$C$4:$C1003,"2026-12",$D$4:$D1003,"Venda") -> 0 | M15: =J15 - K15 - L15 -> 0 | N15: =IFERROR(__xludf.DUMMYFUNCTION("IFERROR(MEDIAN(FILTER($F$4:$F1003,$C$4:$C1003=""12/2026"",$D$4:$D1003=""Compra""), ), 0 )"),0.0) -> 0 | O15: =L15/250 * N15 -> 0
B16: 46046 | C16: =(TEXT(B16,"mm/yyyy")) -> 01/2026 | D16: Compra | E16: 125 | F16: 53.5 | G16: =E16/250 * F16 -> 26.75
B17: 46047 | C17: =(TEXT(B17,"mm/yyyy")) -> 01/2026 | D17: Compra | E17: 125 | F17: 53.5 | G17: =E17/250 * F17 -> 26.75
B18: 46048 | C18: =(TEXT(B18,"mm/yyyy")) -> 01/2026 | D18: Compra | E18: 250 | F18: 53.5 | G18: =E18/250 * F18 -> 53.5
B19: 46049 | C19: =(TEXT(B19,"mm/yyyy")) -> 01/2026 | D19: Compra | E19: 250 | F19: 53.5 | G19: =E19/250 * F19 -> 53.5
B20: 46050 | C20: =(TEXT(B20,"mm/yyyy")) -> 01/2026 | D20: Compra | E20: 500 | F20: 53.5 | G20: =E20/250 * F20 -> 107
B21: 46051 | C21: =(TEXT(B21,"mm/yyyy")) -> 01/2026 | D21: Compra | E21: 250 | F21: 53.5 | G21: =E21/250 * F21 -> 53.5
B22: 46056 | C22: =(TEXT(B22,"mm/yyyy")) -> 02/2026 | D22: Compra | E22: 250 | F22: 53 | G22: =E22/250 * F22 -> 53
B23: 46056 | C23: =(TEXT(B23,"mm/yyyy")) -> 02/2026 | D23: Uso | E23: 30 | F23: 52 | G23: =E23/250 * F23 -> 6.24
B24: 46056 | C24: =(TEXT(B24,"mm/yyyy")) -> 02/2026 | D24: Compra | E24: 250 | F24: 52 | G24: =E24/250 * F24 -> 52
B25: 46056 | C25: =(TEXT(B25,"mm/yyyy")) -> 02/2026 | D25: Venda | E25: 4500 | F25: 52 | G25: =E25/250 * F25 -> 936
B26: 46057 | C26: =(TEXT(B26,"mm/yyyy")) -> 02/2026 | D26: Uso | E26: 30 | F26: 52 | G26: =E26/250 * F26 -> 6.24
B27: 46057 | C27: =(TEXT(B27,"mm/yyyy")) -> 02/2026 | D27: Compra | E27: 100 | F27: 52 | G27: =E27/250 * F27 -> 20.8
... B71: 46112 | C71: =(TEXT(B71,"mm/yyyy")) -> 03/2026 | D71: Compra | E71: 500 | F71: 51 | G71: =E71/250 * F71 -> 102

Sheet Janeiro
B2: Configurações
B3: R$/ 250TC | C3: 53.5
B4: Meta (TC) | C4: 5000
B6: Data | C6: Preço TC | D6: Rotações | E6: Hunts | F6: Drops | G6: Total KKs | H6: Total TC | I6: Total R$ | J6: Jogou? | L6: Resumo Mensal | Q6: Planejamento Mensal
B7: 46023 | C7: 42109 | D7: =167994 + 1548572 + 120000 + 120000 + 267951 + 820000 -> 3044517 | E7: =550826 + 129869 + 1013243 + 404530 + 554361 -> 2652829 | F7: 0 | G7: =IF(SUM(D7:F7) = 0, , (SUM(D7:F7))) -> 5697346 | H7: =IFERROR(G7/C7, ) -> 135.29996 | I7: =IFERROR(H7/25 * ($C$3/10), ) -> 28.954191 | J7: =IF(B7 > TODAY(), "", IF(G7 = "", "Não", "Sim")) -> Sim | M7: KK | N7: TC | O7: R$ | R7: Mediana
B8: 46024 | C8: 42112 | D8: =313472 + 1375312 + 173622 + 160000 + 110000 + 18814 + 67431 -> 2218651 | E8: =1097537 + 503876 + 610570 -> 2211983 | F8: 0 | G8: =IF(SUM(D8:F8) = 0, , (SUM(D8:F8))) -> 4430634 | H8: =IFERROR(G8/C8, ) -> 105.21072 | I8: =IFERROR(H8/25 * ($C$3/10), ) -> 22.515095 | J8: =IF(B8 > TODAY(), "", IF(G8 = "", "Não", "Sim")) -> Sim | L8: Coin Mediana | M8: =IFERROR(MEDIAN(C7:C1002), ) -> 40575.5 | Q8: Dias do mês | R8: =Count(B:B) -> 31
B9: 46025 | C9: 42111 | D9: =197407 + 1759037 + 163500 + 90000 + 99816 + 2093151 + 69771 + 1942337 -> 6415019 | E9: =1191122 + 1006251 -> 2197373 | F9: 0 | G9: =IF(SUM(D9:F9) = 0, , (SUM(D9:F9))) -> 8612392 | H9: =IFERROR(G9/C9, ) -> 204.51644 | I9: =IFERROR(H9/25 * ($C$3/10), ) -> 43.766519 | J9: =IF(B9 > TODAY(), "", IF(G9 = "", "Não", "Sim")) -> Sim | L9: Farm Mediana | M9: =IFERROR(MEDIAN(G7:G1002), ) -> 8763490.5 | N9: =IFERROR(MEDIAN(H7:H1002), ) -> 213.42332 | O9: =IFERROR($N$9 * ($C$3/10) / 25, ) -> 45.67259 | Q9: Dias jogados | R9: =COUNTIF(J:J, "=Sim") -> 24
B10: 46026 | C10: 41998 | D10: =1756010 + 164300 + 1486597 + 1926305 -> 5333212 | E10: =999820 + 1043465 + 1055806 -> 3099091 | F10: 0 | G10: =IF(SUM(D10:F10) = 0, , (SUM(D10:F10))) -> 8432303 | H10: =IFERROR(G10/C10, ) -> 200.77868 | I10: =IFERROR(H10/25 * ($C$3/10), ) -> 42.966638 | J10: =IF(B10 > TODAY(), "", IF(G10 = "", "Não", "Sim")) -> Sim | L10: Farm Total | M10: =IFERROR(SUM(G7:G1002), ) -> 214209070 | N10: =IFERROR($M$10 / $M$8, ) -> 5279.2712 | O10: =IFERROR($N$10 * ($C$3/10) / 25, ) -> 1129.764 | Q10: Dias p/ meta | R10: =IFERROR(M12/M9, ) -> -1.293043
B11: 46027 | C11: 41630 | D11: =2315285 + 153000 + 141642 + 2201739 + 1916046 -> 6727712 | E11: =1598004 + 1447321 -> 3045325 | F11: 0 | G11: =IF(SUM(D11:F11) = 0, , (SUM(D11:F11))) -> 9773037 | H11: =IFERROR(G11/C11, ) -> 234.75948 | I11: =IFERROR(H11/25 * ($C$3/10), ) -> 50.238528 | J11: =IF(B11 > TODAY(), "", IF(G11 = "", "Não", "Sim")) -> Sim | L11: Meta | M11: =IFERROR($N$11 * $M$8, ) -> 202877500 | N11: =IFERROR($C$4, ) -> 5000 | O11: =IFERROR($N$11 * ($C$3/10) / 25,"") -> 1070 | Q11: Folgas realizadas | R11: =COUNTIF($J:$J, "=Não") -> 7
B12: 46028 | C12: 41444 | D12: =1565618 + 1568560 + 290621 -> 3424799 | E12: =1711196 + 1170458 -> 2881654 | F12: 0 | G12: =IF(SUM(D12:F12) = 0, , (SUM(D12:F12))) -> 6306453 | H12: =IFERROR(G12/C12, ) -> 152.16806 | I12: =IFERROR(H12/25 * ($C$3/10), ) -> 32.563964 | J12: =IF(B12 > TODAY(), "", IF(G12 = "", "Não", "Sim")) -> Sim | L12: Restante | M12: =IFERROR($M$11 - $M$10, ) -> -11331570 | N12: =N11 - N10 -> -279.27124 | O12: =IFERROR($N$12 * ($C$3/10) / 25, ) -> -59.764044 | Q12: Folgas Possíveis | R12: =R8 - R9 - R10 -> 8.293043
B13: 46029 | C13: 41217 | D13: =1735564 + 163500 + 2276253 + 1728506 -> 5903823 | E13: =680335 + 1098787 + 758470 + 473174 -> 3010766 | F13: 0 | G13: =IF(SUM(D13:F13) = 0, , (SUM(D13:F13))) -> 8914589 | H13: =IFERROR(G13/C13, ) -> 216.28428 | I13: =IFERROR(H13/25 * ($C$3/10), ) -> 46.284835 | J13: =IF(B13 > TODAY(), "", IF(G13 = "", "Não", "Sim")) -> Sim | Q13: Status | R13: =IF(M10 >= M11, "🔵 Concluído", IF((R8-R9)-R10-R11>=2, "🟢 Seguro", IF((R8-R9)-R10-R11>=0, "🟡 Atenção", "🔴 Risco"))) -> 🔵 Concluído
B14: 46030 | C14: 41139 | D14: =2575533 + 163000 + 97740 + 2201549 + 1927205 -> 6965027 | E14: =1899421 + 1134533 -> 3033954 | F14: 0 | G14: =IF(SUM(D14:F14) = 0, , (SUM(D14:F14))) -> 9998981 | H14: =IFERROR(G14/C14, ) -> 243.05357 | I14: =IFERROR(H14/25 * ($C$3/10), ) -> 52.013465 | J14: =IF(B14 > TODAY(), "", IF(G14 = "", "Não", "Sim")) -> Sim
B15: 46031 | C15: 40899 | D15: =1434849 + 163500 + 1714377 + 2272429 -> 5585155 | E15: =1066541 + 1663890 + 296204 -> 3026635 | F15: 0 | G15: =IF(SUM(D15:F15) = 0, , (SUM(D15:F15))) -> 8611790 | H15: =IFERROR(G15/C15, ) -> 210.56236 | I15: =IFERROR(H15/25 * ($C$3/10), ) -> 45.060345 | J15: =IF(B15 > TODAY(), "", IF(G15 = "", "Não", "Sim")) -> Sim
B16: 46032 | C16: 40899 | D16: =2309409 + 163500 + 1779944 + 1920816 -> 6173669 | E16: =2054601 + 1020522 -> 3075123 | F16: 0 | G16: =IF(SUM(D16:F16) = 0, , (SUM(D16:F16))) -> 9248792 | H16: =IFERROR(G16/C16, ) -> 226.13736 | I16: =IFERROR(H16/25 * ($C$3/10), ) -> 48.393396 | J16: =IF(B16 > TODAY(), "", IF(G16 = "", "Não", "Sim")) -> Sim
B17: 46033 | C17: 41142 | D17: =2309841 + 153000 + 2135854 + 2546316 -> 7145011 | E17: =1571057 + 1497217 + 1807300 -> 4875574 | F17: 0 | G17: =IF(SUM(D17:F17) = 0, , (SUM(D17:F17))) -> 12020585 | H17: =IFERROR(G17/C17, ) -> 292.17308 | I17: =IFERROR(H17/25 * ($C$3/10), ) -> 62.52504 | J17: =IF(B17 > TODAY(), "", IF(G17 = "", "Não", "Sim")) -> Sim
B18: 46034 | G18: =IF(SUM(D18:F18) = 0, , (SUM(D18:F18))) | H18: =IFERROR(G18/C18, ) | I18: =IFERROR(H18/25 * ($C$3/10), ) -> 0 | J18: =IF(B18 > TODAY(), "", IF(G18 = "", "Não", "Sim")) -> Não
B19: 46035 | G19: =IF(SUM(D19:F19) = 0, , (SUM(D19:F19))) | H19: =IFERROR(G19/C19, ) | I19: =IFERROR(H19/25 * ($C$3/10), ) -> 0 | J19: =IF(B19 > TODAY(), "", IF(G19 = "", "Não", "Sim")) -> Não
B20: 46036 | G20: =IF(SUM(D20:F20) = 0, , (SUM(D20:F20))) | H20: =IFERROR(G20/C20, ) | I20: =IFERROR(H20/25 * ($C$3/10), ) -> 0 | J20: =IF(B20 > TODAY(), "", IF(G20 = "", "Não", "Sim")) -> Não
B21: 46037 | G21: =IF(SUM(D21:F21) = 0, , (SUM(D21:F21))) | H21: =IFERROR(G21/C21, ) | I21: =IFERROR(H21/25 * ($C$3/10), ) -> 0 | J21: =IF(B21 > TODAY(), "", IF(G21 = "", "Não", "Sim")) -> Não
B22: 46038 | G22: =IF(SUM(D22:F22) = 0, , (SUM(D22:F22))) | H22: =IFERROR(G22/C22, ) | I22: =IFERROR(H22/25 * ($C$3/10), ) -> 0 | J22: =IF(B22 > TODAY(), "", IF(G22 = "", "Não", "Sim")) -> Não
B23: 46039 | G23: =IF(SUM(D23:F23) = 0, , (SUM(D23:F23))) | H23: =IFERROR(G23/C23, ) | I23: =IFERROR(H23/25 * ($C$3/10), ) -> 0 | J23: =IF(B23 > TODAY(), "", IF(G23 = "", "Não", "Sim")) -> Não
B24: 46040 | G24: =IF(SUM(D24:F24) = 0, , (SUM(D24:F24))) | H24: =IFERROR(G24/C24, ) | I24: =IFERROR(H24/25 * ($C$3/10), ) -> 0 | J24: =IF(B24 > TODAY(), "", IF(G24 = "", "Não", "Sim")) -> Não
B25: 46041 | C25: 40175 | D25: =120000 + 2484713 + 99000 + 2140344 + 210941 -> 5054998 | E25: 0 | F25: 0 | G25: =IF(SUM(D25:F25) = 0, , (SUM(D25:F25))) -> 5054998 | H25: =IFERROR(G25/C25, ) -> 125.82447 | I25: =IFERROR(H25/25 * ($C$3/10), ) -> 26.926436 | J25: =IF(B25 > TODAY(), "", IF(G25 = "", "Não", "Sim")) -> Sim
B26: 46042 | C26: 39980 | D26: =2281649 + 2561986 + 1397116 -> 6240751 | E26: =1311458 + 1714693 -> 3026151 | F26: 0 | G26: =IF(SUM(D26:F26) = 0, , (SUM(D26:F26))) -> 9266902 | H26: =IFERROR(G26/C26, ) -> 231.78844 | I26: =IFERROR(H26/25 * ($C$3/10), ) -> 49.602727 | J26: =IF(B26 > TODAY(), "", IF(G26 = "", "Não", "Sim")) -> Sim
B27: 46043 | C27: 40746 | D27: =1893737 + 2375352 - 139158 + 1872003 -> 6001934 | E27: =1757438 + 1391518 + 299214 + 361708 -> 3809878 | F27: 0 | G27: =IF(SUM(D27:F27) = 0, , (SUM(D27:F27))) -> 9811812 | H27: =IFERROR(G27/C27, ) -> 240.8043 | I27: =IFERROR(H27/25 * ($C$3/10), ) -> 51.53212 | J27: =IF(B27 > TODAY(), "", IF(G27 = "", "Não", "Sim")) -> Sim
B28: 46044 | C28: 39880 | D28: =2520699 + 1775867 + 1791258 + 1100000 -> 7187824 | E28: =2701580 + 1226080 -> 3927660 | F28: 0 | G28: =IF(SUM(D28:F28) = 0, , (SUM(D28:F28))) -> 11115484 | H28: =IFERROR(G28/C28, ) -> 278.72327 | I28: =IFERROR(H28/25 * ($C$3/10), ) -> 59.64678 | J28: =IF(B28 > TODAY(), "", IF(G28 = "", "Não", "Sim")) -> Sim
B29: 46045 | C29: 39794 | D29: =2644077 + 1534120 + 120000 + 1613835 + 1855796 -> 7767828 | E29: =1761539 + 1280279 -> 3041818 | F29: 0 | G29: =IF(SUM(D29:F29) = 0, , (SUM(D29:F29))) -> 10809646 | H29: =IFERROR(G29/C29, ) -> 271.6401 | I29: =IFERROR(H29/25 * ($C$3/10), ) -> 58.130981 | J29: =IF(B29 > TODAY(), "", IF(G29 = "", "Não", "Sim")) -> Sim
B30: 46046 | C30: 38790 | D30: =1834596 + 2469163 -> 4303759 | E30: =950435 + 1644889 + 413743 -> 3009067 | F30: 0 | G30: =IF(SUM(D30:F30) = 0, , (SUM(D30:F30))) -> 7312826 | H30: =IFERROR(G30/C30, ) -> 188.52349 | I30: =IFERROR(H30/25 * ($C$3/10), ) -> 40.344026 | J30: =IF(B30 > TODAY(), "", IF(G30 = "", "Não", "Sim")) -> Sim
B31: 46047 | C31: 40341 | D31: =1676549 + 2071499 + 1842584 + 1302567 + 418499 -> 7311698 | E31: =1008485 + 791398 + 1250139 + 267006 + 128013 -> 3445041 | F31: 0 | G31: =IF(SUM(D31:F31) = 0, , (SUM(D31:F31))) -> 10756739 | H31: =IFERROR(G31/C31, ) -> 266.64532 | I31: =IFERROR(H31/25 * ($C$3/10), ) -> 57.062099 | J31: =IF(B31 > TODAY(), "", IF(G31 = "", "Não", "Sim")) -> Sim
B32: 46048 | C32: 39400 | D32: =2253300 + 2175651 + 722611 + 2120896 -> 7272458 | E32: =1525000 + 1475962 -> 3000962 | F32: 0 | G32: =IF(SUM(D32:F32) = 0, , (SUM(D32:F32))) -> 10273420 | H32: =IFERROR(G32/C32, ) -> 260.7467 | I32: =IFERROR(H32/25 * ($C$3/10), ) -> 55.799794 | J32: =IF(B32 > TODAY(), "", IF(G32 = "", "Não", "Sim")) -> Sim
B33: 46049 | C33: 39199 | D33: =1741188 + 1986816 + 1777323 -> 5505327 | E33: =1256435 + 551514 + 202339 -> 2010288 | F33: 0 | G33: =IF(SUM(D33:F33) = 0, , (SUM(D33:F33))) -> 7515615 | H33: =IFERROR(G33/C33, ) -> 191.72976 | I33: =IFERROR(H33/25 * ($C$3/10), ) -> 41.030169 | J33: =IF(B33 > TODAY(), "", IF(G33 = "", "Não", "Sim")) -> Sim
B34: 46050 | C34: 39988 | D34: =2429564 + 2122643 + 2504837 -> 7057044 | E34: =831674 + 422586 + 866053 -> 2120313 | F34: =2500000 + 12000000 -> 14500000 | G34: =IF(SUM(D34:F34) = 0, , (SUM(D34:F34))) -> 23677357 | H34: =IFERROR(G34/C34, ) -> 592.11156 | I34: =IFERROR(H34/25 * ($C$3/10), ) -> 126.71187 | J34: =IF(B34 > TODAY(), "", IF(G34 = "", "Não", "Sim")) -> Sim
B35: 46051 | C35: 39466 | D35: =2383164 + 1743470 -> 4126634 | E35: =670316 + 1020070 + 747444 -> 2437830 | F35: 0 | G35: =IF(SUM(D35:F35) = 0, , (SUM(D35:F35))) -> 6564464 | H35: =IFERROR(G35/C35, ) -> 166.33213 | I35: =IFERROR(H35/25 * ($C$3/10), ) -> 35.595077 | J35: =IF(B35 > TODAY(), "", IF(G35 = "", "Não", "Sim")) -> Sim
B36: 46052 | C36: 40405 | D36: =1500424 + 2086308 + 350000 + 2014381 -> 5951113 | E36: =222731 + 1476958 -> 1699689 | F36: 0 | G36: =IF(SUM(D36:F36) = 0, , (SUM(D36:F36))) -> 7650802 | H36: =IFERROR(G36/C36, ) -> 189.35285 | I36: =IFERROR(H36/25 * ($C$3/10), ) -> 40.52151 | J36: =IF(B36 > TODAY(), "", IF(G36 = "", "Não", "Sim")) -> Sim
B37: 46053 | C37: 39792 | D37: =165238 + 105566 + 31083 -> 301887 | E37: =852127 + 1198089 -> 2050216 | F37: 0 | G37: =IF(SUM(D37:F37) = 0, , (SUM(D37:F37))) -> 2352103 | H37: =IFERROR(G37/C37, ) -> 59.109947 | I37: =IFERROR(H37/25 * ($C$3/10), ) -> 12.649529 | J37: =IF(B37 > TODAY(), "", IF(G37 = "", "Não", "Sim")) -> Sim

Sheet Fevereiro
B2: Configurações
B3: R$/ 250TC | C3: 52
B4: Meta (TC) | C4: 5000
B6: Data | C6: Preço TC | D6: Rotações | E6: Hunts | F6: Drops | G6: Total KKs | H6: Total TC | I6: Total R$ | J6: Jogou? | L6: Resumo Mensal | Q6: Planejamento Mensal
B7: 46054 | C7: 40295 | D7: 0 | E7: =1360418 + 453357 + 1201815 -> 3015590 | F7: 1003000 | G7: =IF(SUM(D7:F7) = 0, , (SUM(D7:F7))) -> 4018590 | H7: =IFERROR(G7/C7, ) -> 99.729247 | I7: =IFERROR(H7/25 * ($C$3/10), ) -> 20.743683 | J7: =IF(B7 > TODAY(), "", IF(G7 = "", "Não", "Sim")) -> Sim | M7: KK | N7: TC | O7: R$ | R7: Mediana
B8: 46055 | C8: 40280 | D8: =2674389 + 2368712 -> 5043101 | E8: =312122 + 390948 + 1250283 + 22470 + 767303 + 116161 -> 2859287 | F8: 0 | G8: =IF(SUM(D8:F8) = 0, , (SUM(D8:F8))) -> 7902388 | H8: =IFERROR(G8/C8, ) -> 196.1864 | I8: =IFERROR(H8/25 * ($C$3/10), ) -> 40.80677 | J8: =IF(B8 > TODAY(), "", IF(G8 = "", "Não", "Sim")) -> Sim | L8: Coin Mediana | M8: =IFERROR(MEDIAN(C7:C999), ) -> 39997 | Q8: Dias do mês | R8: =Count(B:B) -> 28
B9: 46056 | C9: 39600 | D9: =1506430 + 1765197 + 241039 + 1986028 -> 5498694 | E9: =578311 + 230504 + 1201934 -> 2010749 | F9: 0 | G9: =IF(SUM(D9:F9) = 0, , (SUM(D9:F9))) -> 7509443 | H9: =IFERROR(G9/C9, ) -> 189.6324 | I9: =IFERROR(H9/25 * ($C$3/10), ) -> 39.443539 | J9: =IF(B9 > TODAY(), "", IF(G9 = "", "Não", "Sim")) -> Sim | L9: Farm Mediana | M9: =IFERROR(MEDIAN(G7:G999), ) -> 7936121 | N9: =IFERROR(MEDIAN(H7:H999), ) -> 202.19302 | O9: =IFERROR($N$9 * ($C$3/10) / 25, ) -> 42.056149 | Q9: Dias jogados | R9: =COUNTIF(J:J, "=Sim") -> 28
B10: 46057 | C10: 40267 | D10: =2249023 + 2128596 + 1754379 -> 6131998 | E10: =447856 + 251698 + 499735 + 825812 -> 2025101 | F10: =1300001 -> 1300001 | G10: =IF(SUM(D10:F10) = 0, , (SUM(D10:F10))) -> 9457100 | H10: =IFERROR(G10/C10, ) -> 234.85981 | I10: =IFERROR(H10/25 * ($C$3/10), ) -> 48.850841 | J10: =IF(B10 > TODAY(), "", IF(G10 = "", "Não", "Sim")) -> Sim | L10: Farm Total | M10: =IFERROR(SUM(G7:G999), ) -> 216933187 | N10: =IFERROR($M$10 / $M$8, ) -> 5423.7365 | O10: =IFERROR($N$10 * ($C$3/10) / 25, ) -> 1128.1372 | Q10: Dias p/ meta | R10: =IFERROR(M12/M9, ) -> -2.1355757
B11: 46058 | C11: 40280 | D11: =1527491 + 1930428 + 231970 + 1339895 -> 5029784 | E11: =538058 + 199448 + 1289065 -> 2026571 | F11: 0 | G11: =IF(SUM(D11:F11) = 0, , (SUM(D11:F11))) -> 7056355 | H11: =IFERROR(G11/C11, ) -> 175.1826 | I11: =IFERROR(H11/25 * ($C$3/10), ) -> 36.43798 | J11: =IF(B11 > TODAY(), "", IF(G11 = "", "Não", "Sim")) -> Sim | L11: Meta | M11: =IFERROR($N$11 * $M$8, ) -> 199985000 | N11: =IFERROR($C$4, ) -> 5000 | O11: =IFERROR($N$11 * ($C$3/10) / 25,"") -> 1040 | Q11: Folgas realizadas | R11: =COUNTIF($J:$J, "=Não") -> 0
B12: 46059 | C12: 40239 | D12: =1655133 + 333912 + 1304621 + 1810221 -> 5103887 | E12: =473491 + 391340 + 314099 -> 1178930 | F12: 0 | G12: =IF(SUM(D12:F12) = 0, , (SUM(D12:F12))) -> 6282817 | H12: =IFERROR(G12/C12, ) -> 156.1375 | I12: =IFERROR(H12/25 * ($C$3/10), ) -> 32.476601 | J12: =IF(B12 > TODAY(), "", IF(G12 = "", "Não", "Sim")) -> Sim | L12: Restante | M12: =IFERROR($M$11 - $M$10, ) -> -16948187 | N12: =N11 - N10 -> -423.73646 | O12: =IFERROR($N$12 * ($C$3/10) / 25, ) -> -88.137183 | Q12: Folgas Possíveis | R12: =R8 - R9 - R10 -> 2.1355757
B13: 46060 | C13: 40236 | D13: =2077003 + 277899 + 2068134 + 1556443 + 229224 -> 6208703 | E13: 0 | F13: 0 | G13: =IF(SUM(D13:F13) = 0, , (SUM(D13:F13))) -> 6208703 | H13: =IFERROR(G13/C13, ) -> 154.30716 | I13: =IFERROR(H13/25 * ($C$3/10), ) -> 32.09589 | J13: =IF(B13 > TODAY(), "", IF(G13 = "", "Não", "Sim")) -> Sim | Q13: Status | R13: =IF(M10 >= M11, "🔵 Concluído", IF((R8-R9)-R10-R11>=2, "🟢 Seguro", IF((R8-R9)-R10-R11>=0, "🟡 Atenção", "🔴 Risco"))) -> 🔵 Concluído
B14: 46061 | C14: 40220 | D14: =1796174 + 1797803 + 1900163 -> 5494140 | E14: =386656 + 414192 -> 800848 | F14: 0 | G14: =IF(SUM(D14:F14) = 0, , (SUM(D14:F14))) -> 6294988 | H14: =IFERROR(G14/C14, ) -> 156.51387 | I14: =IFERROR(H14/25 * ($C$3/10), ) -> 32.554886 | J14: =IF(B14 > TODAY(), "", IF(G14 = "", "Não", "Sim")) -> Sim
B15: 46062 | C15: 39999 | D15: =1678855 + 1355761 + 273377 + 640345 + 3414423 -> 7362761 | E15: =279215 + 1244147 + 516595 -> 2039957 | F15: 0 | G15: =IF(SUM(D15:F15) = 0, , (SUM(D15:F15))) -> 9402718 | H15: =IFERROR(G15/C15, ) -> 235.07383 | I15: =IFERROR(H15/25 * ($C$3/10), ) -> 48.895356 | J15: =IF(B15 > TODAY(), "", IF(G15 = "", "Não", "Sim")) -> Sim
B16: 46063 | C16: 40190 | D16: =2249677 + 1511530 + 1736185 + 431197 + 214963 -> 6143552 | E16: =514567 + 445515 + 614622 -> 1574704 | F16: 0 | G16: =IF(SUM(D16:F16) = 0, , (SUM(D16:F16))) -> 7718256 | H16: =IFERROR(G16/C16, ) -> 192.04419 | I16: =IFERROR(H16/25 * ($C$3/10), ) -> 39.945192 | J16: =IF(B16 > TODAY(), "", IF(G16 = "", "Não", "Sim")) -> Sim
B17: 46064 | C17: 39999 | D17: =1666022 + 1687145 + 200451 + 2163428 + 139273 -> 5856319 | E17: =2014817 + 994511 -> 3009328 | F17: 0 | G17: =IF(SUM(D17:F17) = 0, , (SUM(D17:F17))) -> 8865647 | H17: =IFERROR(G17/C17, ) -> 221.64672 | I17: =IFERROR(H17/25 * ($C$3/10), ) -> 46.102517 | J17: =IF(B17 > TODAY(), "", IF(G17 = "", "Não", "Sim")) -> Sim
B18: 46065 | C18: 39970 | D18: =2578230 + 1802960 + 179580 + 1638831 -> 6199601 | E18: =1692802 + 1321926 -> 3014728 | F18: 0 | G18: =IF(SUM(D18:F18) = 0, , (SUM(D18:F18))) -> 9214329 | H18: =IFERROR(G18/C18, ) -> 230.53112 | I18: =IFERROR(H18/25 * ($C$3/10), ) -> 47.950474 | J18: =IF(B18 > TODAY(), "", IF(G18 = "", "Não", "Sim")) -> Sim
B19: 46066 | C19: 40281 | D19: =2237671 + 314431 + 1480663 + 193427 + 1998383 -> 6224575 | E19: =1725086 + 1315733 + 90539 -> 3131358 | F19: 0 | G19: =IF(SUM(D19:F19) = 0, , (SUM(D19:F19))) -> 9355933 | H19: =IFERROR(G19/C19, ) -> 232.26665 | I19: =IFERROR(H19/25 * ($C$3/10), ) -> 48.311464 | J19: =IF(B19 > TODAY(), "", IF(G19 = "", "Não", "Sim")) -> Sim
B20: 46067 | C20: 40281 | D20: =2172110 + 1483320 + 1515393 -> 5170823 | E20: =1507885 + 447451 + 1074387 -> 3029723 | F20: 0 | G20: =IF(SUM(D20:F20) = 0, , (SUM(D20:F20))) -> 8200546 | H20: =IFERROR(G20/C20, ) -> 203.58348 | I20: =IFERROR(H20/25 * ($C$3/10), ) -> 42.345363 | J20: =IF(B20 > TODAY(), "", IF(G20 = "", "Não", "Sim")) -> Sim
B21: 46068 | C21: 40161 | D21: =62442 + 12000 + 87027 -> 161469 | E21: =1810182 + 1218495 + 63916 -> 3092593 | F21: 2000000 | G21: =IF(SUM(D21:F21) = 0, , (SUM(D21:F21))) -> 5254062 | H21: =IFERROR(G21/C21, ) -> 130.82498 | I21: =IFERROR(H21/25 * ($C$3/10), ) -> 27.211596 | J21: =IF(B21 > TODAY(), "", IF(G21 = "", "Não", "Sim")) -> Sim
B22: 46069 | C22: 40135 | D22: =2372893 + 2385960 + 298891 + 1216199 + 285827 -> 6559770 | E22: =1629537 + 1386818 + 378064 + 532517 -> 3926936 | F22: 0 | G22: =IF(SUM(D22:F22) = 0, , (SUM(D22:F22))) -> 10486706 | H22: =IFERROR(G22/C22, ) -> 261.28581 | I22: =IFERROR(H22/25 * ($C$3/10), ) -> 54.347449 | J22: =IF(B22 > TODAY(), "", IF(G22 = "", "Não", "Sim")) -> Sim
B23: 46070 | C23: 39898 | D23: =2213556 + 2339062 + 1500000 -> 6052618 | E23: =1493583 + 1539703 -> 3033286 | F23: 0 | G23: =IF(SUM(D23:F23) = 0, , (SUM(D23:F23))) -> 9085904 | H23: =IFERROR(G23/C23, ) -> 227.72831 | I23: =IFERROR(H23/25 * ($C$3/10), ) -> 47.367488 | J23: =IF(B23 > TODAY(), "", IF(G23 = "", "Não", "Sim")) -> Sim
B24: 46071 | C24: 39895 | D24: =2155715 + 1998684 + 1335007 -> 5489406 | E24: =1588340 + 1472595 -> 3060935 | F24: 0 | G24: =IF(SUM(D24:F24) = 0, , (SUM(D24:F24))) -> 8550341 | H24: =IFERROR(G24/C24, ) -> 214.32112 | I24: =IFERROR(H24/25 * ($C$3/10), ) -> 44.578793 | J24: =IF(B24 > TODAY(), "", IF(G24 = "", "Não", "Sim")) -> Sim
B25: 46072 | C25: 39995 | D25: =1836107 + 2613065 + 2086138 + 289143 -> 6824453 | E25: =2114541 + 889622 -> 3004163 | F25: 0 | G25: =IF(SUM(D25:F25) = 0, , (SUM(D25:F25))) -> 9828616 | H25: =IFERROR(G25/C25, ) -> 245.74612 | I25: =IFERROR(H25/25 * ($C$3/10), ) -> 51.115193 | J25: =IF(B25 > TODAY(), "", IF(G25 = "", "Não", "Sim")) -> Sim
B26: 46073 | C26: 39955 | D26: =1998072 + 2133998 + 1492185 -> 5624255 | E26: =2130880 + 875187 + 120724 -> 3126791 | F26: 0 | G26: =IF(SUM(D26:F26) = 0, , (SUM(D26:F26))) -> 8751046 | H26: =IFERROR(G26/C26, ) -> 219.02255 | I26: =IFERROR(H26/25 * ($C$3/10), ) -> 45.55669 | J26: =IF(B26 > TODAY(), "", IF(G26 = "", "Não", "Sim")) -> Sim
B27: 46074 | C27: 39690 | D27: =1189090 + 2062134 + 1243442 -> 4494666 | E27: =2168972 + 1306216 -> 3475188 | F27: 0 | G27: =IF(SUM(D27:F27) = 0, , (SUM(D27:F27))) -> 7969854 | H27: =IFERROR(G27/C27, ) -> 200.80257 | I27: =IFERROR(H27/25 * ($C$3/10), ) -> 41.766935 | J27: =IF(B27 > TODAY(), "", IF(G27 = "", "Não", "Sim")) -> Sim
B28: 46075 | C28: 39520 | D28: 0 | E28: =1866887 + 1202571 -> 3069458 | F28: 0 | G28: =IF(SUM(D28:F28) = 0, , (SUM(D28:F28))) -> 3069458 | H28: =IFERROR(G28/C28, ) -> 77.668472 | I28: =IFERROR(H28/25 * ($C$3/10), ) -> 16.155042 | J28: =IF(B28 > TODAY(), "", IF(G28 = "", "Não", "Sim")) -> Sim
B29: 46076 | C29: 39388 | D29: =1698307 + 1695121 + 1633477 -> 5026905 | E29: =1876609 + 1132191 -> 3008800 | F29: 0 | G29: =IF(SUM(D29:F29) = 0, , (SUM(D29:F29))) -> 8035705 | H29: =IFERROR(G29/C29, ) -> 204.01404 | I29: =IFERROR(H29/25 * ($C$3/10), ) -> 42.43492 | J29: =IF(B29 > TODAY(), "", IF(G29 = "", "Não", "Sim")) -> Sim
B30: 46077 | C30: 38785 | D30: =1647994 + 1601641 + 481118 -> 3730753 | E30: =200000 + 772593 + 1041591 + 991773 -> 3005957 | F30: 0 | G30: =IF(SUM(D30:F30) = 0, , (SUM(D30:F30))) -> 6736710 | H30: =IFERROR(G30/C30, ) -> 173.6937 | I30: =IFERROR(H30/25 * ($C$3/10), ) -> 36.128289 | J30: =IF(B30 > TODAY(), "", IF(G30 = "", "Não", "Sim")) -> Sim
B31: 46078 | C31: 38800 | D31: 0 | E31: =2006719 + 1009334 -> 3016053 | F31: =3501014 -> 3501014 | G31: =IF(SUM(D31:F31) = 0, , (SUM(D31:F31))) -> 6517067 | H31: =IFERROR(G31/C31, ) -> 167.96564 | I31: =IFERROR(H31/25 * ($C$3/10), ) -> 34.936854 | J31: =IF(B31 > TODAY(), "", IF(G31 = "", "Não", "Sim")) -> Sim
B32: 46079 | C32: 38791 | D32: =1759338 + 141084 + 230551 + 2618822 + 118845 + 1636492 -> 6505132 | E32: =2018614 + 1029843 -> 3048457 | F32: 0 | G32: =IF(SUM(D32:F32) = 0, , (SUM(D32:F32))) -> 9553589 | H32: =IFERROR(G32/C32, ) -> 246.28365 | I32: =IFERROR(H32/25 * ($C$3/10), ) -> 51.226999 | J32: =IF(B32 > TODAY(), "", IF(G32 = "", "Não", "Sim")) -> Sim
B33: 46080 | C33: 38771 | D33: =1590068 + 484520 + 766026 + 1352859 -> 4193473 | E33: =1826847 + 1413705 + 466768 -> 3707320 | F33: 0 | G33: =IF(SUM(D33:F33) = 0, , (SUM(D33:F33))) -> 7900793 | H33: =IFERROR(G33/C33, ) -> 203.781 | I33: =IFERROR(H33/25 * ($C$3/10), ) -> 42.386447 | J33: =IF(B33 > TODAY(), "", IF(G33 = "", "Não", "Sim")) -> Sim
B34: 46081 | C34: 38797 | D34: =2404620 - 128910 + 2307912 + 44265 + 32000 + 1839700 -> 6499587 | E34: =749075 + 456861 -> 1205936 | G34: =IF(SUM(D34:F34) = 0, , (SUM(D34:F34))) -> 7705523 | H34: =IFERROR(G34/C34, ) -> 198.61131 | I34: =IFERROR(H34/25 * ($C$3/10), ) -> 41.311153 | J34: =IF(B34 > TODAY(), "", IF(G34 = "", "Não", "Sim")) -> Sim

Sheet Março
B2: Configurações
B3: R$/ 250TC | C3: 51
B4: Meta (TC) | C4: 5000
B6: Data | C6: Preço TC | D6: Rotações | E6: Hunts | F6: Drops | G6: Total KKs | H6: Total TC | I6: Total R$ | J6: Jogou? | L6: Resumo Mensal | Q6: Planejamento Mensal
B7: 46082 | C7: 38600 | D7: =1593215 -> 1593215 | E7: =591201 + 962148 + 560804 + 719069 -> 2833222 | F7: 1300047 | G7: =IF(SUM(D7:F7) = 0, , (SUM(D7:F7))) -> 5726484 | H7: =IFERROR(G7/C7, ) -> 148.35451 | I7: =IFERROR(H7/25 * ($C$3/10), ) -> 30.26432 | J7: =IF(B7 > TODAY(), "", IF(G7 = "", "Não", "Sim")) -> Sim | M7: KK | N7: TC | O7: R$ | R7: Mediana
B8: 46083 | C8: 39298 | D8: =1866433 + 2460609 + 1522293 -> 5849335 | E8: =1006766 + 2005061 -> 3011827 | F8: 0 | G8: =IF(SUM(D8:F8) = 0, , (SUM(D8:F8))) -> 8861162 | H8: =IFERROR(G8/C8, ) -> 225.48634 | I8: =IFERROR(H8/25 * ($C$3/10), ) -> 45.999212 | J8: =IF(B8 > TODAY(), "", IF(G8 = "", "Não", "Sim")) -> Sim | L8: Coin Mediana | M8: =IFERROR(MEDIAN(C7:C999), ) -> 38498 | Q8: Dias do mês | R8: =Count(B:B) -> 31
B9: 46084 | C9: 39888 | D9: =1966898 + 1950000 + 1138419 + 364075 + 829970 -> 6249362 | E9: =1813968 + 895592 -> 2709560 | F9: 0 | G9: =IF(SUM(D9:F9) = 0, , (SUM(D9:F9))) -> 8958922 | H9: =IFERROR(G9/C9, ) -> 224.60194 | I9: =IFERROR(H9/25 * ($C$3/10), ) -> 45.818795 | J9: =IF(B9 > TODAY(), "", IF(G9 = "", "Não", "Sim")) -> Sim | L9: Farm Mediana | M9: =IFERROR(MEDIAN(G7:G999), ) -> 7255621 | N9: =IFERROR(MEDIAN(H7:H999), ) -> 190.69802 | O9: =IFERROR($N$9 * ($C$3/10) / 25, ) -> 38.902395 | Q9: Dias jogados | R9: =COUNTIF(J:J, "=Sim") -> 31
B10: 46085 | C10: 37949 | D10: =2889635 + 1585814 -> 4475449 | E10: =1684132 + 1077218 -> 2761350 | F10: 0 | G10: =IF(SUM(D10:F10) = 0, , (SUM(D10:F10))) -> 7236799 | H10: =IFERROR(G10/C10, ) -> 190.69802 | I10: =IFERROR(H10/25 * ($C$3/10), ) -> 38.902395 | J10: =IF(B10 > TODAY(), "", IF(G10 = "", "Não", "Sim")) -> Sim | L10: Farm Total | M10: =IFERROR(SUM(G7:G999), ) -> 208999761 | N10: =IFERROR($M$10 / $M$8, ) -> 5428.8472 | O10: =IFERROR($N$10 * ($C$3/10) / 25, ) -> 1107.4848 | Q10: Dias p/ meta | R10: =IFERROR(M12/M9, ) -> -2.2754442
B11: 46086 | C11: 37900 | D11: =1370867 + 1359419 + 1500000 -> 4230286 | E11: =1870522 + 1180452 -> 3050974 | F11: 0 | G11: =IF(SUM(D11:F11) = 0, , (SUM(D11:F11))) -> 7281260 | H11: =IFERROR(G11/C11, ) -> 192.11768 | I11: =IFERROR(H11/25 * ($C$3/10), ) -> 39.192006 | J11: =IF(B11 > TODAY(), "", IF(G11 = "", "Não", "Sim")) -> Sim | L11: Meta | M11: =IFERROR($N$11 * $M$8, ) -> 192490000 | N11: =IFERROR($C$4, ) -> 5000 | O11: =IFERROR($N$11 * ($C$3/10) / 25,"") -> 1020 | Q11: Folgas realizadas | R11: =COUNTIF($J:$J, "=Não") -> 0
B12: 46087 | C12: 38993 | D12: 0 | E12: =944578 + 1211390 + 858872 -> 3014840 | F12: 0 | G12: =IF(SUM(D12:F12) = 0, , (SUM(D12:F12))) -> 3014840 | H12: =IFERROR(G12/C12, ) -> 77.317467 | I12: =IFERROR(H12/25 * ($C$3/10), ) -> 15.772763 | J12: =IF(B12 > TODAY(), "", IF(G12 = "", "Não", "Sim")) -> Sim | L12: Restante | M12: =IFERROR($M$11 - $M$10, ) -> -16509761 | N12: =N11 - N10 -> -428.84724 | O12: =IFERROR($N$12 * ($C$3/10) / 25, ) -> -87.484837 | Q12: Folgas Possíveis | R12: =R8 - R9 - R10 -> 2.2754442
B13: 46088 | C13: 38099 | D13: =296185 + 86358 + 408589 -> 791132 | E13: =1263502 + 509101 + 1230129 -> 3002732 | F13: 0 | G13: =IF(SUM(D13:F13) = 0, , (SUM(D13:F13))) -> 3793864 | H13: =IFERROR(G13/C13, ) -> 99.579097 | I13: =IFERROR(H13/25 * ($C$3/10), ) -> 20.314136 | J13: =IF(B13 > TODAY(), "", IF(G13 = "", "Não", "Sim")) -> Sim | Q13: Status | R13: =IF(M10 >= M11, "🔵 Concluído", IF((R8-R9)-R10-R11>=2, "🟢 Seguro", IF((R8-R9)-R10-R11>=0, "🟡 Atenção", "🔴 Risco"))) -> 🔵 Concluído
B14: 46089 | C14: 38095 | D14: =1287862 + 1627561 -> 2915423 | E14: =1959894 + 952496 + 92467 -> 3004857 | F14: 0 | G14: =IF(SUM(D14:F14) = 0, , (SUM(D14:F14))) -> 5920280 | H14: =IFERROR(G14/C14, ) -> 155.40832 | I14: =IFERROR(H14/25 * ($C$3/10), ) -> 31.703298 | J14: =IF(B14 > TODAY(), "", IF(G14 = "", "Não", "Sim")) -> Sim
B15: 46090 | C15: 38498 | D15: =2611132 + 1217971 + 1744899 + 247550 + 704766 -> 6526318 | E15: =1826907 + 1209214 -> 3036121 | F15: 0 | G15: =IF(SUM(D15:F15) = 0, , (SUM(D15:F15))) -> 9562439 | H15: =IFERROR(G15/C15, ) -> 248.38794 | I15: =IFERROR(H15/25 * ($C$3/10), ) -> 50.67114 | J15: =IF(B15 > TODAY(), "", IF(G15 = "", "Não", "Sim")) -> Sim
B16: 46091 | C16: 38198 | D16: =2126989 -> 2126989 | E16: =1795121 + 945185 -> 2740306 | F16: 0 | G16: =IF(SUM(D16:F16) = 0, , (SUM(D16:F16))) -> 4867295 | H16: =IFERROR(G16/C16, ) -> 127.42277 | I16: =IFERROR(H16/25 * ($C$3/10), ) -> 25.994245 | J16: =IF(B16 > TODAY(), "", IF(G16 = "", "Não", "Sim")) -> Sim
B17: 46092 | C17: 38196 | D17: =1821921 - 130627 + 2605544 + 1388582 -> 5685420 | E17: =1586198 + 546884 -> 2133082 | F17: 0 | G17: =IF(SUM(D17:F17) = 0, , (SUM(D17:F17))) -> 7818502 | H17: =IFERROR(G17/C17, ) -> 204.69426 | I17: =IFERROR(H17/25 * ($C$3/10), ) -> 41.757629 | J17: =IF(B17 > TODAY(), "", IF(G17 = "", "Não", "Sim")) -> Sim
B18: 46093 | C18: 38193 | D18: =1910486 + 913030 + 1527523 + 536720 + 720150 + 426128 -> 6034037 | E18: =2026332 + 1024892 -> 3051224 | F18: 0 | G18: =IF(SUM(D18:F18) = 0, , (SUM(D18:F18))) -> 9085261 | H18: =IFERROR(G18/C18, ) -> 237.87765 | I18: =IFERROR(H18/25 * ($C$3/10), ) -> 48.52704 | J18: =IF(B18 > TODAY(), "", IF(G18 = "", "Não", "Sim")) -> Sim
B19: 46094 | C19: 38099 | D19: =1546936 + 2700897 + 579935 -> 4827768 | E19: =2026592 + 852012 + 170320 -> 3048924 | F19: 0 | G19: =IF(SUM(D19:F19) = 0, , (SUM(D19:F19))) -> 7876692 | H19: =IFERROR(G19/C19, ) -> 206.74275 | I19: =IFERROR(H19/25 * ($C$3/10), ) -> 42.175521 | J19: =IF(B19 > TODAY(), "", IF(G19 = "", "Não", "Sim")) -> Sim
B20: 46095 | C20: 38499 | D20: 0 | E20: =1886119 + 475758 + 652933 -> 3014810 | F20: 0 | G20: =IF(SUM(D20:F20) = 0, , (SUM(D20:F20))) -> 3014810 | H20: =IFERROR(G20/C20, ) -> 78.308787 | I20: =IFERROR(H20/25 * ($C$3/10), ) -> 15.974993 | J20: =IF(B20 > TODAY(), "", IF(G20 = "", "Não", "Sim")) -> Sim
B21: 46096 | C21: 37900 | D21: 0 | E21: =1975845 + 1035061 -> 3010906 | F21: 0 | G21: =IF(SUM(D21:F21) = 0, , (SUM(D21:F21))) -> 3010906 | H21: =IFERROR(G21/C21, ) -> 79.44343 | I21: =IFERROR(H21/25 * ($C$3/10), ) -> 16.20646 | J21: =IF(B21 > TODAY(), "", IF(G21 = "", "Não", "Sim")) -> Sim
B22: 46097 | C22: 39000 | D22: =2486527 + 2303716 + 1849927 -> 6640170 | E22: =803013 + 399194 + 447648 + 1509043 -> 3158898 | F22: 0 | G22: =IF(SUM(D22:F22) = 0, , (SUM(D22:F22))) -> 9799068 | H22: =IFERROR(G22/C22, ) -> 251.25815 | I22: =IFERROR(H22/25 * ($C$3/10), ) -> 51.256663 | J22: =IF(B22 > TODAY(), "", IF(G22 = "", "Não", "Sim")) -> Sim
B23: 46098 | C23: 38798 | D23: =1849473 + 2268903 + 1638113 -> 5756489 | E23: =1478170 + 957265 + 365580 -> 2801015 | F23: 0 | G23: =IF(SUM(D23:F23) = 0, , (SUM(D23:F23))) -> 8557504 | H23: =IFERROR(G23/C23, ) -> 220.5656 | I23: =IFERROR(H23/25 * ($C$3/10), ) -> 44.995382 | J23: =IF(B23 > TODAY(), "", IF(G23 = "", "Não", "Sim")) -> Sim
B24: 46099 | C24: 38000 | D24: =2067247 + 1911185 + 1411664 + 534935 -> 5925031 | E24: =1287719 -> 1287719 | F24: 0 | G24: =IF(SUM(D24:F24) = 0, , (SUM(D24:F24))) -> 7212750 | H24: =IFERROR(G24/C24, ) -> 189.80921 | I24: =IFERROR(H24/25 * ($C$3/10), ) -> 38.721079 | J24: =IF(B24 > TODAY(), "", IF(G24 = "", "Não", "Sim")) -> Sim
B25: 46100 | C25: 38499 | D25: 0 | E25: =1468000 + 131000 + 1100000 -> 2699000 | F25: 0 | G25: =IF(SUM(D25:F25) = 0, , (SUM(D25:F25))) -> 2699000 | H25: =IFERROR(G25/C25, ) -> 70.105717 | I25: =IFERROR(H25/25 * ($C$3/10), ) -> 14.301566 | J25: =IF(B25 > TODAY(), "", IF(G25 = "", "Não", "Sim")) -> Sim
B26: 46101 | C26: 38499 | D26: =1917325 + 1402623 -> 3319948 | E26: =970256 + 675574 + 1114271 -> 2760101 | F26: 0 | G26: =IF(SUM(D26:F26) = 0, , (SUM(D26:F26))) -> 6080049 | H26: =IFERROR(G26/C26, ) -> 157.92745 | I26: =IFERROR(H26/25 * ($C$3/10), ) -> 32.2172 | J26: =IF(B26 > TODAY(), "", IF(G26 = "", "Não", "Sim")) -> Sim
B27: 46102 | C27: 39089 | D27: =1885805 + 2266267 + 2033456 -> 6185528 | E27: =1198329 + 1111696 + 1272996 -> 3583021 | F27: 0 | G27: =IF(SUM(D27:F27) = 0, , (SUM(D27:F27))) -> 9768549 | H27: =IFERROR(G27/C27, ) -> 249.90532 | I27: =IFERROR(H27/25 * ($C$3/10), ) -> 50.980685 | J27: =IF(B27 > TODAY(), "", IF(G27 = "", "Não", "Sim")) -> Sim
B28: 46103 | C28: 37499 | D28: =3325939 + 2371038 + 1486317 -> 7183294 | E28: =997321 + 589056 -> 1586377 | F28: 0 | G28: =IF(SUM(D28:F28) = 0, , (SUM(D28:F28))) -> 8769671 | H28: =IFERROR(G28/C28, ) -> 233.86413 | I28: =IFERROR(H28/25 * ($C$3/10), ) -> 47.708282 | J28: =IF(B28 > TODAY(), "", IF(G28 = "", "Não", "Sim")) -> Sim
B29: 46104 | C29: 38400 | D29: =2288248 + 1454530 + 642926 + 1093751 -> 5479455 | E29: =650780 + 1125386 -> 1776166 | F29: 0 | G29: =IF(SUM(D29:F29) = 0, , (SUM(D29:F29))) -> 7255621 | H29: =IFERROR(G29/C29, ) -> 188.94846 | I29: =IFERROR(H29/25 * ($C$3/10), ) -> 38.545487 | J29: =IF(B29 > TODAY(), "", IF(G29 = "", "Não", "Sim")) -> Sim
B30: 46105 | C30: 38780 | D30: =1779292 + 1620011 + 1536063 -> 4935366 | E30: =1176452 -> 1176452 | F30: 1102015 | G30: =IF(SUM(D30:F30) = 0, , (SUM(D30:F30))) -> 7213833 | H30: =IFERROR(G30/C30, ) -> 186.01942 | I30: =IFERROR(H30/25 * ($C$3/10), ) -> 37.947961 | J30: =IF(B30 > TODAY(), "", IF(G30 = "", "Não", "Sim")) -> Sim
B31: 46106 | C31: 38389 | D31: =1765893 + 1601477 + 1290000 + 2213357 -> 6870727 | E31: =1033000 -> 1033000 | F31: 0 | G31: =IF(SUM(D31:F31) = 0, , (SUM(D31:F31))) -> 7903727 | H31: =IFERROR(G31/C31, ) -> 205.8852 | I31: =IFERROR(H31/25 * ($C$3/10), ) -> 42.000581 | J31: =IF(B31 > TODAY(), "", IF(G31 = "", "Não", "Sim")) -> Sim
B32: 46107 | C32: 38389 | D32: =1432160 + 2032074 -> 3464234 | E32: =1930940 + 1073563 -> 3004503 | F32: 0 | G32: =IF(SUM(D32:F32) = 0, , (SUM(D32:F32))) -> 6468737 | H32: =IFERROR(G32/C32, ) -> 168.50496 | I32: =IFERROR(H32/25 * ($C$3/10), ) -> 34.375012 | J32: =IF(B32 > TODAY(), "", IF(G32 = "", "Não", "Sim")) -> Sim
B33: 46108 | C33: 39200 | D33: =1814408 + 767095 + 2290636 -> 4872139 | E33: =1551609 + 762064 + 588747 -> 2902420 | F33: 0 | G33: =IF(SUM(D33:F33) = 0, , (SUM(D33:F33))) -> 7774559 | H33: =IFERROR(G33/C33, ) -> 198.33059 | I33: =IFERROR(H33/25 * ($C$3/10), ) -> 40.45944 | J33: =IF(B33 > TODAY(), "", IF(G33 = "", "Não", "Sim")) -> Sim
B34: 46109 | C34: 39188 | D34: 0 | E34: =1285390 + 1597669 -> 2883059 | F34: 0 | G34: =IF(SUM(D34:F34) = 0, , (SUM(D34:F34))) -> 2883059 | H34: =IFERROR(G34/C34, ) -> 73.569945 | I34: =IFERROR(H34/25 * ($C$3/10), ) -> 15.008269 | J34: =IF(B34 > TODAY(), "", IF(G34 = "", "Não", "Sim")) -> Sim
B35: 46110 | C35: 39164 | D35: =428136 + 55482 + 390406 -> 874024 | E35: =1711227 + 1110293 -> 2821520 | F35: 0 | G35: =IF(SUM(D35:F35) = 0, , (SUM(D35:F35))) -> 3695544 | H35: =IFERROR(G35/C35, ) -> 94.360739 | I35: =IFERROR(H35/25 * ($C$3/10), ) -> 19.249591 | J35: =IF(B35 > TODAY(), "", IF(G35 = "", "Não", "Sim")) -> Sim
B36: 46111 | C36: 39070 | D36: =1583021 + 1959962 + 1932240 + 751731 -> 6226954 | E36: =1749014 + 1258488 -> 3007502 | F36: 0 | G36: =IF(SUM(D36:F36) = 0, , (SUM(D36:F36))) -> 9234456 | H36: =IFERROR(G36/C36, ) -> 236.35669 | I36: =IFERROR(H36/25 * ($C$3/10), ) -> 48.216765 | J36: =IF(B36 > TODAY(), "", IF(G36 = "", "Não", "Sim")) -> Sim
B37: 46112 | C37: 38399 | D37: =2272686 + 1253537 + 581213 + 508729 -> 4616165 | E37: =1643998 + 1393955 -> 3037953 | F37: 0 | G37: =IF(SUM(D37:F37) = 0, , (SUM(D37:F37))) -> 7654118 | H37: =IFERROR(G37/C37, ) -> 199.33118 | I37: =IFERROR(H37/25 * ($C$3/10), ) -> 40.663561 | J37: =IF(B37 > TODAY(), "", IF(G37 = "", "Não", "Sim")) -> Sim

Sheet Abril
B2: Configurações
B3: R$/ 250TC | C3: 51
B4: Meta (TC) | C4: 5000
B6: Data | C6: Preço TC | D6: Rotações | E6: Hunts | F6: Drops | G6: Total KKs | H6: Total TC | I6: Total R$ | J6: Jogou? | L6: Resumo Mensal | Q6: Planejamento Mensal
B7: 46113 | C7: 38396 | G7: =IF(SUM(D7:F7) = 0, , (SUM(D7:F7))) | H7: =IFERROR(G7/C7, ) -> 0 | I7: =IFERROR(H7/25 * ($C$3/10), ) -> 0 | J7: =IF(B7 > TODAY(), "", IF(G7 = "", "Não", "Sim")) -> Não | M7: KK | N7: TC | O7: R$ | R7: Mediana
B8: 46114 | G8: =IF(SUM(D8:F8) = 0, , (SUM(D8:F8))) | H8: =IFERROR(G8/C8, ) | I8: =IFERROR(H8/25 * ($C$3/10), ) -> 0 | J8: =IF(B8 > TODAY(), "", IF(G8 = "", "Não", "Sim")) | L8: Coin Mediana | M8: =IFERROR(MEDIAN(C7:C998), ) -> 38396 | Q8: Dias do mês | R8: =Count(B:B) -> 30
B9: 46115 | G9: =IF(SUM(D9:F9) = 0, , (SUM(D9:F9))) | H9: =IFERROR(G9/C9, ) | I9: =IFERROR(H9/25 * ($C$3/10), ) -> 0 | J9: =IF(B9 > TODAY(), "", IF(G9 = "", "Não", "Sim")) | L9: Farm Mediana | M9: =IFERROR(MEDIAN(G7:G998), ) | N9: =IFERROR(MEDIAN(H7:H998), ) -> 0 | O9: =IFERROR($N$9 * ($C$3/10) / 25, ) -> 0 | Q9: Dias jogados | R9: =COUNTIF(J:J, "=Sim") -> 0
B10: 46116 | G10: =IF(SUM(D10:F10) = 0, , (SUM(D10:F10))) | H10: =IFERROR(G10/C10, ) | I10: =IFERROR(H10/25 * ($C$3/10), ) -> 0 | J10: =IF(B10 > TODAY(), "", IF(G10 = "", "Não", "Sim")) | L10: Farm Total | M10: =IFERROR(SUM(G7:G998), ) -> 0 | N10: =IFERROR($M$10 / $M$8, ) -> 0 | O10: =IFERROR($N$10 * ($C$3/10) / 25, ) -> 0 | Q10: Dias p/ meta | R10: =IFERROR(M12/M9, )
B11: 46117 | G11: =IF(SUM(D11:F11) = 0, , (SUM(D11:F11))) | H11: =IFERROR(G11/C11, ) | I11: =IFERROR(H11/25 * ($C$3/10), ) -> 0 | J11: =IF(B11 > TODAY(), "", IF(G11 = "", "Não", "Sim")) | L11: Meta | M11: =IFERROR($N$11 * $M$8, ) -> 191980000 | N11: =IFERROR($C$4, ) -> 5000 | O11: =IFERROR($N$11 * ($C$3/10) / 25,"") -> 1020 | Q11: Folgas realizadas | R11: =COUNTIF($J:$J, "=Não") -> 1
B12: 46118 | G12: =IF(SUM(D12:F12) = 0, , (SUM(D12:F12))) | H12: =IFERROR(G12/C12, ) | I12: =IFERROR(H12/25 * ($C$3/10), ) -> 0 | J12: =IF(B12 > TODAY(), "", IF(G12 = "", "Não", "Sim")) | L12: Restante | M12: =IFERROR($M$11 - $M$10, ) -> 191980000 | N12: =N11 - N10 -> 5000 | O12: =IFERROR($N$12 * ($C$3/10) / 25, ) -> 1020 | Q12: Folgas Possíveis | R12: =R8 - R9 - R10 -> 30
B13: 46119 | G13: =IF(SUM(D13:F13) = 0, , (SUM(D13:F13))) | H13: =IFERROR(G13/C13, ) | I13: =IFERROR(H13/25 * ($C$3/10), ) -> 0 | J13: =IF(B13 > TODAY(), "", IF(G13 = "", "Não", "Sim")) | Q13: Status | R13: =IF(M10 >= M11, "🔵 Concluído", IF((R8-R9)-R10-R11>=2, "🟢 Seguro", IF((R8-R9)-R10-R11>=0, "🟡 Atenção", "🔴 Risco"))) -> 🟢 Seguro
B14: 46120 | G14: =IF(SUM(D14:F14) = 0, , (SUM(D14:F14))) | H14: =IFERROR(G14/C14, ) | I14: =IFERROR(H14/25 * ($C$3/10), ) -> 0 | J14: =IF(B14 > TODAY(), "", IF(G14 = "", "Não", "Sim"))
B15: 46121 | G15: =IF(SUM(D15:F15) = 0, , (SUM(D15:F15))) | H15: =IFERROR(G15/C15, ) | I15: =IFERROR(H15/25 * ($C$3/10), ) -> 0 | J15: =IF(B15 > TODAY(), "", IF(G15 = "", "Não", "Sim"))
B16: 46122 | G16: =IF(SUM(D16:F16) = 0, , (SUM(D16:F16))) | H16: =IFERROR(G16/C16, ) | I16: =IFERROR(H16/25 * ($C$3/10), ) -> 0 | J16: =IF(B16 > TODAY(), "", IF(G16 = "", "Não", "Sim"))
B17: 46123 | G17: =IF(SUM(D17:F17) = 0, , (SUM(D17:F17))) | H17: =IFERROR(G17/C17, ) | I17: =IFERROR(H17/25 * ($C$3/10), ) -> 0 | J17: =IF(B17 > TODAY(), "", IF(G17 = "", "Não", "Sim"))
B18: 46124 | G18: =IF(SUM(D18:F18) = 0, , (SUM(D18:F18))) | H18: =IFERROR(G18/C18, ) | I18: =IFERROR(H18/25 * ($C$3/10), ) -> 0 | J18: =IF(B18 > TODAY(), "", IF(G18 = "", "Não", "Sim"))
B19: 46125 | G19: =IF(SUM(D19:F19) = 0, , (SUM(D19:F19))) | H19: =IFERROR(G19/C19, ) | I19: =IFERROR(H19/25 * ($C$3/10), ) -> 0 | J19: =IF(B19 > TODAY(), "", IF(G19 = "", "Não", "Sim"))
B20: 46126 | G20: =IF(SUM(D20:F20) = 0, , (SUM(D20:F20))) | H20: =IFERROR(G20/C20, ) | I20: =IFERROR(H20/25 * ($C$3/10), ) -> 0 | J20: =IF(B20 > TODAY(), "", IF(G20 = "", "Não", "Sim"))
B21: 46127 | G21: =IF(SUM(D21:F21) = 0, , (SUM(D21:F21))) | H21: =IFERROR(G21/C21, ) | I21: =IFERROR(H21/25 * ($C$3/10), ) -> 0 | J21: =IF(B21 > TODAY(), "", IF(G21 = "", "Não", "Sim"))
B22: 46128 | G22: =IF(SUM(D22:F22) = 0, , (SUM(D22:F22))) | H22: =IFERROR(G22/C22, ) | I22: =IFERROR(H22/25 * ($C$3/10), ) -> 0 | J22: =IF(B22 > TODAY(), "", IF(G22 = "", "Não", "Sim"))
B23: 46129 | G23: =IF(SUM(D23:F23) = 0, , (SUM(D23:F23))) | H23: =IFERROR(G23/C23, ) | I23: =IFERROR(H23/25 * ($C$3/10), ) -> 0 | J23: =IF(B23 > TODAY(), "", IF(G23 = "", "Não", "Sim"))
B24: 46130 | G24: =IF(SUM(D24:F24) = 0, , (SUM(D24:F24))) | H24: =IFERROR(G24/C24, ) | I24: =IFERROR(H24/25 * ($C$3/10), ) -> 0 | J24: =IF(B24 > TODAY(), "", IF(G24 = "", "Não", "Sim"))
B25: 46131 | G25: =IF(SUM(D25:F25) = 0, , (SUM(D25:F25))) | H25: =IFERROR(G25/C25, ) | I25: =IFERROR(H25/25 * ($C$3/10), ) -> 0 | J25: =IF(B25 > TODAY(), "", IF(G25 = "", "Não", "Sim"))
... B36: 46142 | G36: =IF(SUM(D36:F36) = 0, , (SUM(D36:F36))) | H36: =IFERROR(G36/C36, ) | I36: =IFERROR(H36/25 * ($C$3/10), ) -> 0 | J36: =IF(B36 > TODAY(), "", IF(G36 = "", "Não", "Sim"))

Sheet Maio
B2: Configurações
B3: R$/ 250TC
B4: Meta (TC)
B6: Data | C6: Preço TC | D6: Rotações | E6: Hunts | F6: Drops | G6: Total KKs | H6: Total TC | I6: Total R$ | J6: Jogou? | L6: Resumo Mensal | Q6: Planejamento Mensal
B7: 46143 | G7: =IF(SUM(D7:F7) = 0, , (SUM(D7:F7))) | H7: =IFERROR(G7/C7, ) | I7: =IFERROR(H7/25 * ($C$3/10), ) -> 0 | J7: =IF(B7 > TODAY(), "", IF(G7 = "", "Não", "Sim")) | M7: KK | N7: TC | O7: R$ | R7: Mediana
B8: 46144 | G8: =IF(SUM(D8:F8) = 0, , (SUM(D8:F8))) | H8: =IFERROR(G8/C8, ) | I8: =IFERROR(H8/25 * ($C$3/10), ) -> 0 | J8: =IF(B8 > TODAY(), "", IF(G8 = "", "Não", "Sim")) | L8: Coin Mediana | M8: =IFERROR(MEDIAN(C7:C999), ) | Q8: Dias do mês | R8: =Count(B:B) -> 31
B9: 46145 | G9: =IF(SUM(D9:F9) = 0, , (SUM(D9:F9))) | H9: =IFERROR(G9/C9, ) | I9: =IFERROR(H9/25 * ($C$3/10), ) -> 0 | J9: =IF(B9 > TODAY(), "", IF(G9 = "", "Não", "Sim")) | L9: Farm Mediana | M9: =IFERROR(MEDIAN(G7:G999), ) | N9: =IFERROR(MEDIAN(H7:H999), ) | O9: =IFERROR($N$9 * ($C$3/10) / 25, ) -> 0 | Q9: Dias jogados | R9: =COUNTIF(J:J, "=Sim") -> 0
B10: 46146 | G10: =IF(SUM(D10:F10) = 0, , (SUM(D10:F10))) | H10: =IFERROR(G10/C10, ) | I10: =IFERROR(H10/25 * ($C$3/10), ) -> 0 | J10: =IF(B10 > TODAY(), "", IF(G10 = "", "Não", "Sim")) | L10: Farm Total | M10: =IFERROR(SUM(G7:G999), ) -> 0 | N10: =IFERROR($M$10 / $M$8, ) | O10: =IFERROR($N$10 * ($C$3/10) / 25, ) -> 0 | Q10: Dias p/ meta | R10: =IFERROR(M12/M9, )
B11: 46147 | G11: =IF(SUM(D11:F11) = 0, , (SUM(D11:F11))) | H11: =IFERROR(G11/C11, ) | I11: =IFERROR(H11/25 * ($C$3/10), ) -> 0 | J11: =IF(B11 > TODAY(), "", IF(G11 = "", "Não", "Sim")) | L11: Meta | M11: =IFERROR($N$11 * $M$8, ) -> 0 | N11: =IFERROR($C$4, ) | O11: =IFERROR($N$11 * ($C$3/10) / 25,"") -> 0 | Q11: Folgas realizadas | R11: =COUNTIF($J:$J, "=Não") -> 0
B12: 46148 | G12: =IF(SUM(D12:F12) = 0, , (SUM(D12:F12))) | H12: =IFERROR(G12/C12, ) | I12: =IFERROR(H12/25 * ($C$3/10), ) -> 0 | J12: =IF(B12 > TODAY(), "", IF(G12 = "", "Não", "Sim")) | L12: Restante | M12: =IFERROR($M$11 - $M$10, ) -> 0 | N12: =N11 - N10 -> 0 | O12: =IFERROR($N$12 * ($C$3/10) / 25, ) -> 0 | Q12: Folgas Possíveis | R12: =R8 - R9 - R10 -> 31
B13: 46149 | G13: =IF(SUM(D13:F13) = 0, , (SUM(D13:F13))) | H13: =IFERROR(G13/C13, ) | I13: =IFERROR(H13/25 * ($C$3/10), ) -> 0 | J13: =IF(B13 > TODAY(), "", IF(G13 = "", "Não", "Sim")) | Q13: Status | R13: =IF(M10 >= M11, "🔵 Concluído", IF((R8-R9)-R10-R11>=2, "🟢 Seguro", IF((R8-R9)-R10-R11>=0, "🟡 Atenção", "🔴 Risco"))) -> 🔵 Concluído
B14: 46150 | G14: =IF(SUM(D14:F14) = 0, , (SUM(D14:F14))) | H14: =IFERROR(G14/C14, ) | I14: =IFERROR(H14/25 * ($C$3/10), ) -> 0 | J14: =IF(B14 > TODAY(), "", IF(G14 = "", "Não", "Sim"))
B15: 46151 | G15: =IF(SUM(D15:F15) = 0, , (SUM(D15:F15))) | H15: =IFERROR(G15/C15, ) | I15: =IFERROR(H15/25 * ($C$3/10), ) -> 0 | J15: =IF(B15 > TODAY(), "", IF(G15 = "", "Não", "Sim"))
B16: 46152 | G16: =IF(SUM(D16:F16) = 0, , (SUM(D16:F16))) | H16: =IFERROR(G16/C16, ) | I16: =IFERROR(H16/25 * ($C$3/10), ) -> 0 | J16: =IF(B16 > TODAY(), "", IF(G16 = "", "Não", "Sim"))
B17: 46153 | G17: =IF(SUM(D17:F17) = 0, , (SUM(D17:F17))) | H17: =IFERROR(G17/C17, ) | I17: =IFERROR(H17/25 * ($C$3/10), ) -> 0 | J17: =IF(B17 > TODAY(), "", IF(G17 = "", "Não", "Sim"))
B18: 46154 | G18: =IF(SUM(D18:F18) = 0, , (SUM(D18:F18))) | H18: =IFERROR(G18/C18, ) | I18: =IFERROR(H18/25 * ($C$3/10), ) -> 0 | J18: =IF(B18 > TODAY(), "", IF(G18 = "", "Não", "Sim"))
B19: 46155 | G19: =IF(SUM(D19:F19) = 0, , (SUM(D19:F19))) | H19: =IFERROR(G19/C19, ) | I19: =IFERROR(H19/25 * ($C$3/10), ) -> 0 | J19: =IF(B19 > TODAY(), "", IF(G19 = "", "Não", "Sim"))
B20: 46156 | G20: =IF(SUM(D20:F20) = 0, , (SUM(D20:F20))) | H20: =IFERROR(G20/C20, ) | I20: =IFERROR(H20/25 * ($C$3/10), ) -> 0 | J20: =IF(B20 > TODAY(), "", IF(G20 = "", "Não", "Sim"))
B21: 46157 | G21: =IF(SUM(D21:F21) = 0, , (SUM(D21:F21))) | H21: =IFERROR(G21/C21, ) | I21: =IFERROR(H21/25 * ($C$3/10), ) -> 0 | J21: =IF(B21 > TODAY(), "", IF(G21 = "", "Não", "Sim"))
B22: 46158 | G22: =IF(SUM(D22:F22) = 0, , (SUM(D22:F22))) | H22: =IFERROR(G22/C22, ) | I22: =IFERROR(H22/25 * ($C$3/10), ) -> 0 | J22: =IF(B22 > TODAY(), "", IF(G22 = "", "Não", "Sim"))
B23: 46159 | G23: =IF(SUM(D23:F23) = 0, , (SUM(D23:F23))) | H23: =IFERROR(G23/C23, ) | I23: =IFERROR(H23/25 * ($C$3/10), ) -> 0 | J23: =IF(B23 > TODAY(), "", IF(G23 = "", "Não", "Sim"))
B24: 46160 | G24: =IF(SUM(D24:F24) = 0, , (SUM(D24:F24))) | H24: =IFERROR(G24/C24, ) | I24: =IFERROR(H24/25 * ($C$3/10), ) -> 0 | J24: =IF(B24 > TODAY(), "", IF(G24 = "", "Não", "Sim"))
B25: 46161 | G25: =IF(SUM(D25:F25) = 0, , (SUM(D25:F25))) | H25: =IFERROR(G25/C25, ) | I25: =IFERROR(H25/25 * ($C$3/10), ) -> 0 | J25: =IF(B25 > TODAY(), "", IF(G25 = "", "Não", "Sim"))
... B34: 46170 | G34: =IF(SUM(D34:F34) = 0, , (SUM(D34:F34))) | H34: =IFERROR(G34/C34, ) | I34: =IFERROR(H34/25 * ($C$3/10), ) -> 0 | J34: =IF(B34 > TODAY(), "", IF(G34 = "", "Não", "Sim"))
B35: 46171 | G35: =IF(SUM(D35:F35) = 0, , (SUM(D35:F35))) | I35: =IFERROR(H35/25 * ($C$3/10), ) -> 0 | J35: =IF(B35 > TODAY(), "", IF(G35 = "", "Não", "Sim"))
B36: 46172 | G36: =IF(SUM(D36:F36) = 0, , (SUM(D36:F36))) | H36: =IFERROR(G35/C35, ) | I36: =IFERROR(H36/25 * ($C$3/10), ) -> 0 | J36: =IF(B36 > TODAY(), "", IF(G36 = "", "Não", "Sim"))
B37: 46173 | G37: =IF(SUM(D37:F37) = 0, , (SUM(D37:F37))) | H37: =IFERROR(G37/C37, ) | I37: =IFERROR(H37/25 * ($C$3/10), ) -> 0 | J37: =IF(B37 > TODAY(), "", IF(G37 = "", "Não", "Sim"))

Sheet Junho
B2: Configurações
B3: R$/ 250TC
B4: Meta (TC)
B6: Data | C6: Preço TC | D6: Rotações | E6: Hunts | F6: Drops | G6: Total KKs | H6: Total TC | I6: Total R$ | J6: Jogou? | L6: Resumo Mensal | Q6: Planejamento Mensal
B7: 46174 | G7: =IF(SUM(D7:F7) = 0, , (SUM(D7:F7))) | H7: =IFERROR(G7/C7, ) | I7: =IFERROR(H7/25 * ($C$3/10), ) -> 0 | J7: =IF(B7 > TODAY(), "", IF(G7 = "", "Não", "Sim")) | M7: KK | N7: TC | O7: R$ | R7: Mediana
B8: 46175 | G8: =IF(SUM(D8:F8) = 0, , (SUM(D8:F8))) | H8: =IFERROR(G8/C8, ) | I8: =IFERROR(H8/25 * ($C$3/10), ) -> 0 | J8: =IF(B8 > TODAY(), "", IF(G8 = "", "Não", "Sim")) | L8: Coin Mediana | M8: =IFERROR(MEDIAN(C7:C998), ) | Q8: Dias do mês | R8: =Count(B:B) -> 30
B9: 46176 | G9: =IF(SUM(D9:F9) = 0, , (SUM(D9:F9))) | H9: =IFERROR(G9/C9, ) | I9: =IFERROR(H9/25 * ($C$3/10), ) -> 0 | J9: =IF(B9 > TODAY(), "", IF(G9 = "", "Não", "Sim")) | L9: Farm Mediana | M9: =IFERROR(MEDIAN(G7:G998), ) | N9: =IFERROR(MEDIAN(H7:H998), ) | O9: =IFERROR($N$9 * ($C$3/10) / 25, ) -> 0 | Q9: Dias jogados | R9: =COUNTIF(J:J, "=Sim") -> 0
B10: 46177 | G10: =IF(SUM(D10:F10) = 0, , (SUM(D10:F10))) | H10: =IFERROR(G10/C10, ) | I10: =IFERROR(H10/25 * ($C$3/10), ) -> 0 | J10: =IF(B10 > TODAY(), "", IF(G10 = "", "Não", "Sim")) | L10: Farm Total | M10: =IFERROR(SUM(G7:G998), ) -> 0 | N10: =IFERROR($M$10 / $M$8, ) | O10: =IFERROR($N$10 * ($C$3/10) / 25, ) -> 0 | Q10: Dias p/ meta | R10: =IFERROR(M12/M9, )
B11: 46178 | G11: =IF(SUM(D11:F11) = 0, , (SUM(D11:F11))) | H11: =IFERROR(G11/C11, ) | I11: =IFERROR(H11/25 * ($C$3/10), ) -> 0 | J11: =IF(B11 > TODAY(), "", IF(G11 = "", "Não", "Sim")) | L11: Meta | M11: =IFERROR($N$11 * $M$8, ) -> 0 | N11: =IFERROR($C$4, ) | O11: =IFERROR($N$11 * ($C$3/10) / 25,"") -> 0 | Q11: Folgas realizadas | R11: =COUNTIF($J:$J, "=Não") -> 0
B12: 46179 | G12: =IF(SUM(D12:F12) = 0, , (SUM(D12:F12))) | H12: =IFERROR(G12/C12, ) | I12: =IFERROR(H12/25 * ($C$3/10), ) -> 0 | J12: =IF(B12 > TODAY(), "", IF(G12 = "", "Não", "Sim")) | L12: Restante | M12: =IFERROR($M$11 - $M$10, ) -> 0 | N12: =N11 - N10 -> 0 | O12: =IFERROR($N$12 * ($C$3/10) / 25, ) -> 0 | Q12: Folgas Possíveis | R12: =R8 - R9 - R10 -> 30
